[2024-06-22 20:49:05,768-root] : INFO You are in Home page .
[2024-06-22 20:49:16,337-root] : INFO You are in Home page .
[2024-06-22 20:54:25,745-root] : INFO You are in Home page .
[2024-06-22 20:54:35,064-root] : INFO You are in Home page .
[2024-06-22 21:09:44,290-root] : INFO You are in Home page .
[2024-06-22 21:09:48,800-root] : INFO You are in Home page .
[2024-06-22 21:14:53,122-root] : INFO You are in Home page .
[2024-06-22 21:15:05,419-root] : INFO You are in Home page .
[2024-06-22 21:15:12,269-root] : INFO You are in Home page .
[2024-06-22 21:16:11,871-root] : INFO You are in Home page .
[2024-06-22 21:16:18,369-root] : ERROR 
            Exception occurred in script 
            file : E:\DataScience\Ineuron Projects free\Text_to_speech_Application\Text_To_Speech_SRC\components\text_to_speech.py,
            line number : 33
            error message : No text to speak
        
[2024-06-22 21:16:18,639-root] : INFO You are in Home page .
[2024-06-22 21:16:18,828-django.request] : ERROR Internal Server Error: /get_mp3/
Traceback (most recent call last):
  File "E:\DataScience\Ineuron Projects free\Text_to_speech_Application\Text_To_Speech_SRC\components\text_to_speech.py", line 33, in get_text_to_speech
    tts=gTTS(text=text,lang='en',tld=accent)
  File "e:\DataScience\Ineuron Projects free\Text_to_speech_Application\venv\lib\site-packages\gtts\tts.py", line 133, in __init__
    assert text, "No text to speak"
AssertionError: No text to speak

During handling of the above exception, another exception occurred:

Traceback (most recent call last):
  File "e:\DataScience\Ineuron Projects free\Text_to_speech_Application\venv\lib\site-packages\django\core\handlers\exception.py", line 55, in inner
    response = get_response(request)
  File "e:\DataScience\Ineuron Projects free\Text_to_speech_Application\venv\lib\site-packages\django\core\handlers\base.py", line 197, in _get_response
    response = wrapped_callback(request, *callback_args, **callback_kwargs)
  File "e:\DataScience\Ineuron Projects free\Text_to_speech_Application\venv\lib\site-packages\django\views\decorators\csrf.py", line 56, in wrapper_view
    return view_func(*args, **kwargs)
  File "E:\DataScience\Ineuron Projects free\Text_to_speech_Application\text_to_speech_app\views.py", line 25, in get_mp3
    audio_string=TextToSpeechApplication().get_text_to_speech(text=text,accent=tld)
  File "E:\DataScience\Ineuron Projects free\Text_to_speech_Application\Text_To_Speech_SRC\components\text_to_speech.py", line 47, in get_text_to_speech
    raise TextSpeechException(e,sys)
Text_To_Speech_SRC.exception.TextSpeechException: 
            Exception occurred in script 
            file : E:\DataScience\Ineuron Projects free\Text_to_speech_Application\Text_To_Speech_SRC\components\text_to_speech.py,
            line number : 33
            error message : No text to speak
        
[2024-06-22 21:16:20,532-root] : INFO You are in Home page .
[2024-06-22 21:16:20,627-root] : ERROR 
            Exception occurred in script 
            file : E:\DataScience\Ineuron Projects free\Text_to_speech_Application\Text_To_Speech_SRC\components\text_to_speech.py,
            line number : 33
            error message : No text to speak
        
[2024-06-22 21:16:20,699-django.request] : ERROR Internal Server Error: /get_mp3/
Traceback (most recent call last):
  File "E:\DataScience\Ineuron Projects free\Text_to_speech_Application\Text_To_Speech_SRC\components\text_to_speech.py", line 33, in get_text_to_speech
    tts=gTTS(text=text,lang='en',tld=accent)
  File "e:\DataScience\Ineuron Projects free\Text_to_speech_Application\venv\lib\site-packages\gtts\tts.py", line 133, in __init__
    assert text, "No text to speak"
AssertionError: No text to speak

During handling of the above exception, another exception occurred:

Traceback (most recent call last):
  File "e:\DataScience\Ineuron Projects free\Text_to_speech_Application\venv\lib\site-packages\django\core\handlers\exception.py", line 55, in inner
    response = get_response(request)
  File "e:\DataScience\Ineuron Projects free\Text_to_speech_Application\venv\lib\site-packages\django\core\handlers\base.py", line 197, in _get_response
    response = wrapped_callback(request, *callback_args, **callback_kwargs)
  File "e:\DataScience\Ineuron Projects free\Text_to_speech_Application\venv\lib\site-packages\django\views\decorators\csrf.py", line 56, in wrapper_view
    return view_func(*args, **kwargs)
  File "E:\DataScience\Ineuron Projects free\Text_to_speech_Application\text_to_speech_app\views.py", line 25, in get_mp3
    audio_string=TextToSpeechApplication().get_text_to_speech(text=text,accent=tld)
  File "E:\DataScience\Ineuron Projects free\Text_to_speech_Application\Text_To_Speech_SRC\components\text_to_speech.py", line 47, in get_text_to_speech
    raise TextSpeechException(e,sys)
Text_To_Speech_SRC.exception.TextSpeechException: 
            Exception occurred in script 
            file : E:\DataScience\Ineuron Projects free\Text_to_speech_Application\Text_To_Speech_SRC\components\text_to_speech.py,
            line number : 33
            error message : No text to speak
        
[2024-06-22 21:16:24,883-root] : INFO You are in Home page .
[2024-06-22 21:16:30,060-root] : INFO You are in Home page .
[2024-06-22 21:16:30,135-root] : ERROR 
            Exception occurred in script 
            file : E:\DataScience\Ineuron Projects free\Text_to_speech_Application\Text_To_Speech_SRC\components\text_to_speech.py,
            line number : 33
            error message : No text to speak
        
[2024-06-22 21:16:30,203-django.request] : ERROR Internal Server Error: /get_mp3/
Traceback (most recent call last):
  File "E:\DataScience\Ineuron Projects free\Text_to_speech_Application\Text_To_Speech_SRC\components\text_to_speech.py", line 33, in get_text_to_speech
    tts=gTTS(text=text,lang='en',tld=accent)
  File "e:\DataScience\Ineuron Projects free\Text_to_speech_Application\venv\lib\site-packages\gtts\tts.py", line 133, in __init__
    assert text, "No text to speak"
AssertionError: No text to speak

During handling of the above exception, another exception occurred:

Traceback (most recent call last):
  File "e:\DataScience\Ineuron Projects free\Text_to_speech_Application\venv\lib\site-packages\django\core\handlers\exception.py", line 55, in inner
    response = get_response(request)
  File "e:\DataScience\Ineuron Projects free\Text_to_speech_Application\venv\lib\site-packages\django\core\handlers\base.py", line 197, in _get_response
    response = wrapped_callback(request, *callback_args, **callback_kwargs)
  File "e:\DataScience\Ineuron Projects free\Text_to_speech_Application\venv\lib\site-packages\django\views\decorators\csrf.py", line 56, in wrapper_view
    return view_func(*args, **kwargs)
  File "E:\DataScience\Ineuron Projects free\Text_to_speech_Application\text_to_speech_app\views.py", line 25, in get_mp3
    audio_string=TextToSpeechApplication().get_text_to_speech(text=text,accent=tld)
  File "E:\DataScience\Ineuron Projects free\Text_to_speech_Application\Text_To_Speech_SRC\components\text_to_speech.py", line 47, in get_text_to_speech
    raise TextSpeechException(e,sys)
Text_To_Speech_SRC.exception.TextSpeechException: 
            Exception occurred in script 
            file : E:\DataScience\Ineuron Projects free\Text_to_speech_Application\Text_To_Speech_SRC\components\text_to_speech.py,
            line number : 33
            error message : No text to speak
        
[2024-06-22 21:19:50,471-root] : INFO You are in Home page .
[2024-06-22 21:20:56,518-root] : INFO You are in Home page .
[2024-06-22 21:21:04,613-root] : INFO You are in Home page .
[2024-06-22 21:21:30,597-root] : INFO You are in Home page .
[2024-06-22 21:21:37,352-root] : INFO You are in Home page .
